Workbook

Sheet Datos
A1: EVM - datos de entrada
A2: Proyecto: | B2: Portal de clientes | C2: Fecha de corte: | D2: 46298
A3: Actividad | B3: BAC ($) | C3: % planificado | D3: % real | E3: AC ($) | G3: Notas
A4: Diseño UX | B4: 8000000 | C4: 1 | D4: 1 | E4: 7200000 | G4: en amarillo lo que se llena (la fila 7 es opcional)
A5: Desarrollo backend | B5: 20000000 | C5: 0.6 | D5: 0.45 | E5: 12000000 | G5: porcentajes en decimal: 0,45 = 45%
A6: Pruebas QA | B6: 6000000 | C6: 0.2 | D6: 0 | E6: 0

Sheet EVM
A1: Cálculos EVM
A2: =Datos!B2&" - corte "&TEXT(Datos!D2,"yyyy-mm-dd") -> Portal de clientes - corte 2026-10-03
A3: Actividad | B3: BAC ($) | C3: AC ($) | D3: PV ($) | E3: EV ($) | F3: CV ($) | G3: SV ($) | H3: CPI | I3: SPI | J3: EAC ($) | K3: ETC ($) | L3: VAC ($) | M3: Estado costo | N3: Estado cronograma
A4: =IF(Datos!A4="","",Datos!A4) -> Diseño UX | B4: =IF($A4="","N/A",Datos!B4) -> 8000000 | C4: =IF($A4="","N/A",Datos!E4) -> 7200000 | D4: =IF($A4="","N/A",Datos!B4*Datos!C4) -> 8000000 | E4: =IF($A4="","N/A",Datos!B4*Datos!D4) -> 8000000 | F4: =IF($A4="","N/A",E4-C4) -> 800000 | G4: =IF($A4="","N/A",E4-D4) -> 0 | H4: =IF($A4="","N/A",IF(C4=0,"N/A",E4/C4)) -> 1.1111111 | I4: =IF($A4="","N/A",IF(D4=0,"N/A",E4/D4)) -> 1 | J4: =IF(ISNUMBER(H4),IF(H4=0,"N/A",B4/H4),"N/A") -> 7200000 | K4: =IF(ISNUMBER(J4),J4-C4,"N/A") -> 0 | L4: =IF(ISNUMBER(J4),B4-J4,"N/A") -> 800000 | M4: =IF(NOT(ISNUMBER(H4)),IF(A4="","","NOT_APPLICABLE"),IF(ROUND(H4,6)>1,"UNDER_BUDGET",IF(ROUND(H4,6)<1,"OVER_BUDGET","ON_BUDGET"))) -> UNDER_BUDGET | N4: =IF(NOT(ISNUMBER(I4)),IF(A4="","","NOT_APPLICABLE"),IF(ROUND(I4,6)>1,"AHEAD_OF_SCHEDULE",IF(ROUND(I4,6)<1,"BEHIND_SCHEDULE","ON_SCHEDULE"))) -> ON_SCHEDULE
A5: =IF(Datos!A5="","",Datos!A5) -> Desarrollo backend | B5: =IF($A5="","N/A",Datos!B5) -> 20000000 | C5: =IF($A5="","N/A",Datos!E5) -> 12000000 | D5: =IF($A5="","N/A",Datos!B5*Datos!C5) -> 12000000 | E5: =IF($A5="","N/A",Datos!B5*Datos!D5) -> 9000000 | F5: =IF($A5="","N/A",E5-C5) -> -3000000 | G5: =IF($A5="","N/A",E5-D5) -> -3000000 | H5: =IF($A5="","N/A",IF(C5=0,"N/A",E5/C5)) -> 0.75 | I5: =IF($A5="","N/A",IF(D5=0,"N/A",E5/D5)) -> 0.75 | J5: =IF(ISNUMBER(H5),IF(H5=0,"N/A",B5/H5),"N/A") -> 26666667 | K5: =IF(ISNUMBER(J5),J5-C5,"N/A") -> 14666667 | L5: =IF(ISNUMBER(J5),B5-J5,"N/A") -> -6666666.7 | M5: =IF(NOT(ISNUMBER(H5)),IF(A5="","","NOT_APPLICABLE"),IF(ROUND(H5,6)>1,"UNDER_BUDGET",IF(ROUND(H5,6)<1,"OVER_BUDGET","ON_BUDGET"))) -> OVER_BUDGET | N5: =IF(NOT(ISNUMBER(I5)),IF(A5="","","NOT_APPLICABLE"),IF(ROUND(I5,6)>1,"AHEAD_OF_SCHEDULE",IF(ROUND(I5,6)<1,"BEHIND_SCHEDULE","ON_SCHEDULE"))) -> BEHIND_SCHEDULE
A6: =IF(Datos!A6="","",Datos!A6) -> Pruebas QA | B6: =IF($A6="","N/A",Datos!B6) -> 6000000 | C6: =IF($A6="","N/A",Datos!E6) -> 0 | D6: =IF($A6="","N/A",Datos!B6*Datos!C6) -> 1200000 | E6: =IF($A6="","N/A",Datos!B6*Datos!D6) -> 0 | F6: =IF($A6="","N/A",E6-C6) -> 0 | G6: =IF($A6="","N/A",E6-D6) -> -1200000 | H6: =IF($A6="","N/A",IF(C6=0,"N/A",E6/C6)) -> N/A | I6: =IF($A6="","N/A",IF(D6=0,"N/A",E6/D6)) -> 0 | J6: =IF(ISNUMBER(H6),IF(H6=0,"N/A",B6/H6),"N/A") -> N/A | K6: =IF(ISNUMBER(J6),J6-C6,"N/A") -> N/A | L6: =IF(ISNUMBER(J6),B6-J6,"N/A") -> N/A | M6: =IF(NOT(ISNUMBER(H6)),IF(A6="","","NOT_APPLICABLE"),IF(ROUND(H6,6)>1,"UNDER_BUDGET",IF(ROUND(H6,6)<1,"OVER_BUDGET","ON_BUDGET"))) -> NOT_APPLICABLE | N6: =IF(NOT(ISNUMBER(I6)),IF(A6="","","NOT_APPLICABLE"),IF(ROUND(I6,6)>1,"AHEAD_OF_SCHEDULE",IF(ROUND(I6,6)<1,"BEHIND_SCHEDULE","ON_SCHEDULE"))) -> BEHIND_SCHEDULE
A7: =IF(Datos!A7="","",Datos!A7) | B7: =IF($A7="","N/A",Datos!B7) -> N/A | C7: =IF($A7="","N/A",Datos!E7) -> N/A | D7: =IF($A7="","N/A",Datos!B7*Datos!C7) -> N/A | E7: =IF($A7="","N/A",Datos!B7*Datos!D7) -> N/A | F7: =IF($A7="","N/A",E7-C7) -> N/A | G7: =IF($A7="","N/A",E7-D7) -> N/A | H7: =IF($A7="","N/A",IF(C7=0,"N/A",E7/C7)) -> N/A | I7: =IF($A7="","N/A",IF(D7=0,"N/A",E7/D7)) -> N/A | J7: =IF(ISNUMBER(H7),IF(H7=0,"N/A",B7/H7),"N/A") -> N/A | K7: =IF(ISNUMBER(J7),J7-C7,"N/A") -> N/A | L7: =IF(ISNUMBER(J7),B7-J7,"N/A") -> N/A | M7: =IF(NOT(ISNUMBER(H7)),IF(A7="","","NOT_APPLICABLE"),IF(ROUND(H7,6)>1,"UNDER_BUDGET",IF(ROUND(H7,6)<1,"OVER_BUDGET","ON_BUDGET"))) | N7: =IF(NOT(ISNUMBER(I7)),IF(A7="","","NOT_APPLICABLE"),IF(ROUND(I7,6)>1,"AHEAD_OF_SCHEDULE",IF(ROUND(I7,6)<1,"BEHIND_SCHEDULE","ON_SCHEDULE")))
A8: Total proyecto | B8: =SUM(B4:B7) -> 34000000 | C8: =SUM(C4:C7) -> 19200000 | D8: =SUM(D4:D7) -> 21200000 | E8: =SUM(E4:E7) -> 17000000 | F8: =SUM(F4:F7) -> -2200000 | G8: =SUM(G4:G7) -> -4200000 | H8: =IF(C8=0,"N/A",E8/C8) -> 0.88541667 | I8: =IF(D8=0,"N/A",E8/D8) -> 0.80188679 | J8: =IF(ISNUMBER(H8),IF(H8=0,"N/A",B8/H8),"N/A") -> 38400000 | K8: =IF(ISNUMBER(J8),J8-C8,"N/A") -> 19200000 | L8: =IF(ISNUMBER(J8),B8-J8,"N/A") -> -4400000 | M8: =IF(NOT(ISNUMBER(H8)),IF(A8="","","NOT_APPLICABLE"),IF(ROUND(H8,6)>1,"UNDER_BUDGET",IF(ROUND(H8,6)<1,"OVER_BUDGET","ON_BUDGET"))) -> OVER_BUDGET | N8: =IF(NOT(ISNUMBER(I8)),IF(A8="","","NOT_APPLICABLE"),IF(ROUND(I8,6)>1,"AHEAD_OF_SCHEDULE",IF(ROUND(I8,6)<1,"BEHIND_SCHEDULE","ON_SCHEDULE"))) -> BEHIND_SCHEDULE

Sheet Comparación API
A1: Excel vs API
A2: Tolerancia montos ($) | B2: 0.01 | D2: COINCIDE | E2: =COUNTIF(G7:G51,"COINCIDE") -> 36
A3: Tolerancia CPI/SPI | B3: 0.0001 | D3: DIFERENTE | E3: =COUNTIF(G7:G51,"DIFERENTE") -> 0
D4: PENDIENTE | E4: =COUNTIF(G7:G51,"PENDIENTE") -> 9
A6: Entidad | B6: Métrica | C6: Excel | D6: API | E6: Diferencia | F6: Tolerancia | G6: Resultado
A7: =IF(EVM!A4="","-",EVM!A4) -> Diseño UX | B7: PV | C7: =EVM!D4 -> 8000000 | D7: 8000000 | E7: =IF(AND(ISNUMBER(C7),ISNUMBER(D7)),C7-D7,"") -> 0 | F7: =$B$2 -> 0.01 | G7: =IF(D7="","PENDIENTE",IF(OR(ISTEXT(C7),ISTEXT(D7)),IF(AND(C7="N/A",D7="null"),"COINCIDE","DIFERENTE"),IF(ABS(C7-D7)<=F7,"COINCIDE","DIFERENTE"))) -> COINCIDE
A8: =IF(EVM!A4="","-",EVM!A4) -> Diseño UX | B8: EV | C8: =EVM!E4 -> 8000000 | D8: 8000000 | E8: =IF(AND(ISNUMBER(C8),ISNUMBER(D8)),C8-D8,"") -> 0 | F8: =$B$2 -> 0.01 | G8: =IF(D8="","PENDIENTE",IF(OR(ISTEXT(C8),ISTEXT(D8)),IF(AND(C8="N/A",D8="null"),"COINCIDE","DIFERENTE"),IF(ABS(C8-D8)<=F8,"COINCIDE","DIFERENTE"))) -> COINCIDE
A9: =IF(EVM!A4="","-",EVM!A4) -> Diseño UX | B9: CV | C9: =EVM!F4 -> 800000 | D9: 800000 | E9: =IF(AND(ISNUMBER(C9),ISNUMBER(D9)),C9-D9,"") -> 0 | F9: =$B$2 -> 0.01 | G9: =IF(D9="","PENDIENTE",IF(OR(ISTEXT(C9),ISTEXT(D9)),IF(AND(C9="N/A",D9="null"),"COINCIDE","DIFERENTE"),IF(ABS(C9-D9)<=F9,"COINCIDE","DIFERENTE"))) -> COINCIDE
A10: =IF(EVM!A4="","-",EVM!A4) -> Diseño UX | B10: SV | C10: =EVM!G4 -> 0 | D10: 0 | E10: =IF(AND(ISNUMBER(C10),ISNUMBER(D10)),C10-D10,"") -> 0 | F10: =$B$2 -> 0.01 | G10: =IF(D10="","PENDIENTE",IF(OR(ISTEXT(C10),ISTEXT(D10)),IF(AND(C10="N/A",D10="null"),"COINCIDE","DIFERENTE"),IF(ABS(C10-D10)<=F10,"COINCIDE","DIFERENTE"))) -> COINCIDE
A11: =IF(EVM!A4="","-",EVM!A4) -> Diseño UX | B11: CPI | C11: =EVM!H4 -> 1.1111111 | D11: 1.1111 | E11: =IF(AND(ISNUMBER(C11),ISNUMBER(D11)),C11-D11,"") -> 1.1111111e-05 | F11: =$B$3 -> 0.0001 | G11: =IF(D11="","PENDIENTE",IF(OR(ISTEXT(C11),ISTEXT(D11)),IF(AND(C11="N/A",D11="null"),"COINCIDE","DIFERENTE"),IF(ABS(C11-D11)<=F11,"COINCIDE","DIFERENTE"))) -> COINCIDE
A12: =IF(EVM!A4="","-",EVM!A4) -> Diseño UX | B12: SPI | C12: =EVM!I4 -> 1 | D12: 1 | E12: =IF(AND(ISNUMBER(C12),ISNUMBER(D12)),C12-D12,"") -> 0 | F12: =$B$3 -> 0.0001 | G12: =IF(D12="","PENDIENTE",IF(OR(ISTEXT(C12),ISTEXT(D12)),IF(AND(C12="N/A",D12="null"),"COINCIDE","DIFERENTE"),IF(ABS(C12-D12)<=F12,"COINCIDE","DIFERENTE"))) -> COINCIDE
A13: =IF(EVM!A4="","-",EVM!A4) -> Diseño UX | B13: EAC | C13: =EVM!J4 -> 7200000 | D13: 7200000 | E13: =IF(AND(ISNUMBER(C13),ISNUMBER(D13)),C13-D13,"") -> 0 | F13: =$B$2 -> 0.01 | G13: =IF(D13="","PENDIENTE",IF(OR(ISTEXT(C13),ISTEXT(D13)),IF(AND(C13="N/A",D13="null"),"COINCIDE","DIFERENTE"),IF(ABS(C13-D13)<=F13,"COINCIDE","DIFERENTE"))) -> COINCIDE
A14: =IF(EVM!A4="","-",EVM!A4) -> Diseño UX | B14: ETC | C14: =EVM!K4 -> 0 | D14: 0 | E14: =IF(AND(ISNUMBER(C14),ISNUMBER(D14)),C14-D14,"") -> 0 | F14: =$B$2 -> 0.01 | G14: =IF(D14="","PENDIENTE",IF(OR(ISTEXT(C14),ISTEXT(D14)),IF(AND(C14="N/A",D14="null"),"COINCIDE","DIFERENTE"),IF(ABS(C14-D14)<=F14,"COINCIDE","DIFERENTE"))) -> COINCIDE
A15: =IF(EVM!A4="","-",EVM!A4) -> Diseño UX | B15: VAC | C15: =EVM!L4 -> 800000 | D15: 800000 | E15: =IF(AND(ISNUMBER(C15),ISNUMBER(D15)),C15-D15,"") -> 0 | F15: =$B$2 -> 0.01 | G15: =IF(D15="","PENDIENTE",IF(OR(ISTEXT(C15),ISTEXT(D15)),IF(AND(C15="N/A",D15="null"),"COINCIDE","DIFERENTE"),IF(ABS(C15-D15)<=F15,"COINCIDE","DIFERENTE"))) -> COINCIDE
A16: =IF(EVM!A5="","-",EVM!A5) -> Desarrollo backend | B16: PV | C16: =EVM!D5 -> 12000000 | D16: 12000000 | E16: =IF(AND(ISNUMBER(C16),ISNUMBER(D16)),C16-D16,"") -> 0 | F16: =$B$2 -> 0.01 | G16: =IF(D16="","PENDIENTE",IF(OR(ISTEXT(C16),ISTEXT(D16)),IF(AND(C16="N/A",D16="null"),"COINCIDE","DIFERENTE"),IF(ABS(C16-D16)<=F16,"COINCIDE","DIFERENTE"))) -> COINCIDE
A17: =IF(EVM!A5="","-",EVM!A5) -> Desarrollo backend | B17: EV | C17: =EVM!E5 -> 9000000 | D17: 9000000 | E17: =IF(AND(ISNUMBER(C17),ISNUMBER(D17)),C17-D17,"") -> 0 | F17: =$B$2 -> 0.01 | G17: =IF(D17="","PENDIENTE",IF(OR(ISTEXT(C17),ISTEXT(D17)),IF(AND(C17="N/A",D17="null"),"COINCIDE","DIFERENTE"),IF(ABS(C17-D17)<=F17,"COINCIDE","DIFERENTE"))) -> COINCIDE
A18: =IF(EVM!A5="","-",EVM!A5) -> Desarrollo backend | B18: CV | C18: =EVM!F5 -> -3000000 | D18: -3000000 | E18: =IF(AND(ISNUMBER(C18),ISNUMBER(D18)),C18-D18,"") -> 0 | F18: =$B$2 -> 0.01 | G18: =IF(D18="","PENDIENTE",IF(OR(ISTEXT(C18),ISTEXT(D18)),IF(AND(C18="N/A",D18="null"),"COINCIDE","DIFERENTE"),IF(ABS(C18-D18)<=F18,"COINCIDE","DIFERENTE"))) -> COINCIDE
A19: =IF(EVM!A5="","-",EVM!A5) -> Desarrollo backend | B19: SV | C19: =EVM!G5 -> -3000000 | D19: -3000000 | E19: =IF(AND(ISNUMBER(C19),ISNUMBER(D19)),C19-D19,"") -> 0 | F19: =$B$2 -> 0.01 | G19: =IF(D19="","PENDIENTE",IF(OR(ISTEXT(C19),ISTEXT(D19)),IF(AND(C19="N/A",D19="null"),"COINCIDE","DIFERENTE"),IF(ABS(C19-D19)<=F19,"COINCIDE","DIFERENTE"))) -> COINCIDE
A20: =IF(EVM!A5="","-",EVM!A5) -> Desarrollo backend | B20: CPI | C20: =EVM!H5 -> 0.75 | D20: 0.75 | E20: =IF(AND(ISNUMBER(C20),ISNUMBER(D20)),C20-D20,"") -> 0 | F20: =$B$3 -> 0.0001 | G20: =IF(D20="","PENDIENTE",IF(OR(ISTEXT(C20),ISTEXT(D20)),IF(AND(C20="N/A",D20="null"),"COINCIDE","DIFERENTE"),IF(ABS(C20-D20)<=F20,"COINCIDE","DIFERENTE"))) -> COINCIDE
A21: =IF(EVM!A5="","-",EVM!A5) -> Desarrollo backend | B21: SPI | C21: =EVM!I5 -> 0.75 | D21: 0.75 | E21: =IF(AND(ISNUMBER(C21),ISNUMBER(D21)),C21-D21,"") -> 0 | F21: =$B$3 -> 0.0001 | G21: =IF(D21="","PENDIENTE",IF(OR(ISTEXT(C21),ISTEXT(D21)),IF(AND(C21="N/A",D21="null"),"COINCIDE","DIFERENTE"),IF(ABS(C21-D21)<=F21,"COINCIDE","DIFERENTE"))) -> COINCIDE
A22: =IF(EVM!A5="","-",EVM!A5) -> Desarrollo backend | B22: EAC | C22: =EVM!J5 -> 26666667 | D22: 26666667 | E22: =IF(AND(ISNUMBER(C22),ISNUMBER(D22)),C22-D22,"") -> -0.0033333339 | F22: =$B$2 -> 0.01 | G22: =IF(D22="","PENDIENTE",IF(OR(ISTEXT(C22),ISTEXT(D22)),IF(AND(C22="N/A",D22="null"),"COINCIDE","DIFERENTE"),IF(ABS(C22-D22)<=F22,"COINCIDE","DIFERENTE"))) -> COINCIDE
A23: =IF(EVM!A5="","-",EVM!A5) -> Desarrollo backend | B23: ETC | C23: =EVM!K5 -> 14666667 | D23: 14666667 | E23: =IF(AND(ISNUMBER(C23),ISNUMBER(D23)),C23-D23,"") -> -0.003333332 | F23: =$B$2 -> 0.01 | G23: =IF(D23="","PENDIENTE",IF(OR(ISTEXT(C23),ISTEXT(D23)),IF(AND(C23="N/A",D23="null"),"COINCIDE","DIFERENTE"),IF(ABS(C23-D23)<=F23,"COINCIDE","DIFERENTE"))) -> COINCIDE
A24: =IF(EVM!A5="","-",EVM!A5) -> Desarrollo backend | B24: VAC | C24: =EVM!L5 -> -6666666.7 | D24: -6666666.7 | E24: =IF(AND(ISNUMBER(C24),ISNUMBER(D24)),C24-D24,"") -> 0.003333332 | F24: =$B$2 -> 0.01 | G24: =IF(D24="","PENDIENTE",IF(OR(ISTEXT(C24),ISTEXT(D24)),IF(AND(C24="N/A",D24="null"),"COINCIDE","DIFERENTE"),IF(ABS(C24-D24)<=F24,"COINCIDE","DIFERENTE"))) -> COINCIDE
A25: =IF(EVM!A6="","-",EVM!A6) -> Pruebas QA | B25: PV | C25: =EVM!D6 -> 1200000 | D25: 1200000 | E25: =IF(AND(ISNUMBER(C25),ISNUMBER(D25)),C25-D25,"") -> 0 | F25: =$B$2 -> 0.01 | G25: =IF(D25="","PENDIENTE",IF(OR(ISTEXT(C25),ISTEXT(D25)),IF(AND(C25="N/A",D25="null"),"COINCIDE","DIFERENTE"),IF(ABS(C25-D25)<=F25,"COINCIDE","DIFERENTE"))) -> COINCIDE
A26: =IF(EVM!A6="","-",EVM!A6) -> Pruebas QA | B26: EV | C26: =EVM!E6 -> 0 | D26: 0 | E26: =IF(AND(ISNUMBER(C26),ISNUMBER(D26)),C26-D26,"") -> 0 | F26: =$B$2 -> 0.01 | G26: =IF(D26="","PENDIENTE",IF(OR(ISTEXT(C26),ISTEXT(D26)),IF(AND(C26="N/A",D26="null"),"COINCIDE","DIFERENTE"),IF(ABS(C26-D26)<=F26,"COINCIDE","DIFERENTE"))) -> COINCIDE
A27: =IF(EVM!A6="","-",EVM!A6) -> Pruebas QA | B27: CV | C27: =EVM!F6 -> 0 | D27: 0 | E27: =IF(AND(ISNUMBER(C27),ISNUMBER(D27)),C27-D27,"") -> 0 | F27: =$B$2 -> 0.01 | G27: =IF(D27="","PENDIENTE",IF(OR(ISTEXT(C27),ISTEXT(D27)),IF(AND(C27="N/A",D27="null"),"COINCIDE","DIFERENTE"),IF(ABS(C27-D27)<=F27,"COINCIDE","DIFERENTE"))) -> COINCIDE
A28: =IF(EVM!A6="","-",EVM!A6) -> Pruebas QA | B28: SV | C28: =EVM!G6 -> -1200000 | D28: -1200000 | E28: =IF(AND(ISNUMBER(C28),ISNUMBER(D28)),C28-D28,"") -> 0 | F28: =$B$2 -> 0.01 | G28: =IF(D28="","PENDIENTE",IF(OR(ISTEXT(C28),ISTEXT(D28)),IF(AND(C28="N/A",D28="null"),"COINCIDE","DIFERENTE"),IF(ABS(C28-D28)<=F28,"COINCIDE","DIFERENTE"))) -> COINCIDE
A29: =IF(EVM!A6="","-",EVM!A6) -> Pruebas QA | B29: CPI | C29: =EVM!H6 -> N/A | D29: null | E29: =IF(AND(ISNUMBER(C29),ISNUMBER(D29)),C29-D29,"") | F29: =$B$3 -> 0.0001 | G29: =IF(D29="","PENDIENTE",IF(OR(ISTEXT(C29),ISTEXT(D29)),IF(AND(C29="N/A",D29="null"),"COINCIDE","DIFERENTE"),IF(ABS(C29-D29)<=F29,"COINCIDE","DIFERENTE"))) -> COINCIDE
A30: =IF(EVM!A6="","-",EVM!A6) -> Pruebas QA | B30: SPI | C30: =EVM!I6 -> 0 | D30: 0 | E30: =IF(AND(ISNUMBER(C30),ISNUMBER(D30)),C30-D30,"") -> 0 | F30: =$B$3 -> 0.0001 | G30: =IF(D30="","PENDIENTE",IF(OR(ISTEXT(C30),ISTEXT(D30)),IF(AND(C30="N/A",D30="null"),"COINCIDE","DIFERENTE"),IF(ABS(C30-D30)<=F30,"COINCIDE","DIFERENTE"))) -> COINCIDE
A31: =IF(EVM!A6="","-",EVM!A6) -> Pruebas QA | B31: EAC | C31: =EVM!J6 -> N/A | D31: null | E31: =IF(AND(ISNUMBER(C31),ISNUMBER(D31)),C31-D31,"") | F31: =$B$2 -> 0.01 | G31: =IF(D31="","PENDIENTE",IF(OR(ISTEXT(C31),ISTEXT(D31)),IF(AND(C31="N/A",D31="null"),"COINCIDE","DIFERENTE"),IF(ABS(C31-D31)<=F31,"COINCIDE","DIFERENTE"))) -> COINCIDE
A32: =IF(EVM!A6="","-",EVM!A6) -> Pruebas QA | B32: ETC | C32: =EVM!K6 -> N/A | D32: null | E32: =IF(AND(ISNUMBER(C32),ISNUMBER(D32)),C32-D32,"") | F32: =$B$2 -> 0.01 | G32: =IF(D32="","PENDIENTE",IF(OR(ISTEXT(C32),ISTEXT(D32)),IF(AND(C32="N/A",D32="null"),"COINCIDE","DIFERENTE"),IF(ABS(C32-D32)<=F32,"COINCIDE","DIFERENTE"))) -> COINCIDE
A33: =IF(EVM!A6="","-",EVM!A6) -> Pruebas QA | B33: VAC | C33: =EVM!L6 -> N/A | D33: null | E33: =IF(AND(ISNUMBER(C33),ISNUMBER(D33)),C33-D33,"") | F33: =$B$2 -> 0.01 | G33: =IF(D33="","PENDIENTE",IF(OR(ISTEXT(C33),ISTEXT(D33)),IF(AND(C33="N/A",D33="null"),"COINCIDE","DIFERENTE"),IF(ABS(C33-D33)<=F33,"COINCIDE","DIFERENTE"))) -> COINCIDE
A34: =IF(EVM!A7="","-",EVM!A7) -> - | B34: PV | C34: =EVM!D7 -> N/A | E34: =IF(AND(ISNUMBER(C34),ISNUMBER(D34)),C34-D34,"") | F34: =$B$2 -> 0.01 | G34: =IF(D34="","PENDIENTE",IF(OR(ISTEXT(C34),ISTEXT(D34)),IF(AND(C34="N/A",D34="null"),"COINCIDE","DIFERENTE"),IF(ABS(C34-D34)<=F34,"COINCIDE","DIFERENTE"))) -> PENDIENTE
A35: =IF(EVM!A7="","-",EVM!A7) -> - | B35: EV | C35: =EVM!E7 -> N/A | E35: =IF(AND(ISNUMBER(C35),ISNUMBER(D35)),C35-D35,"") | F35: =$B$2 -> 0.01 | G35: =IF(D35="","PENDIENTE",IF(OR(ISTEXT(C35),ISTEXT(D35)),IF(AND(C35="N/A",D35="null"),"COINCIDE","DIFERENTE"),IF(ABS(C35-D35)<=F35,"COINCIDE","DIFERENTE"))) -> PENDIENTE
A36: =IF(EVM!A7="","-",EVM!A7) -> - | B36: CV | C36: =EVM!F7 -> N/A | E36: =IF(AND(ISNUMBER(C36),ISNUMBER(D36)),C36-D36,"") | F36: =$B$2 -> 0.01 | G36: =IF(D36="","PENDIENTE",IF(OR(ISTEXT(C36),ISTEXT(D36)),IF(AND(C36="N/A",D36="null"),"COINCIDE","DIFERENTE"),IF(ABS(C36-D36)<=F36,"COINCIDE","DIFERENTE"))) -> PENDIENTE
A37: =IF(EVM!A7="","-",EVM!A7) -> - | B37: SV | C37: =EVM!G7 -> N/A | E37: =IF(AND(ISNUMBER(C37),ISNUMBER(D37)),C37-D37,"") | F37: =$B$2 -> 0.01 | G37: =IF(D37="","PENDIENTE",IF(OR(ISTEXT(C37),ISTEXT(D37)),IF(AND(C37="N/A",D37="null"),"COINCIDE","DIFERENTE"),IF(ABS(C37-D37)<=F37,"COINCIDE","DIFERENTE"))) -> PENDIENTE
A38: =IF(EVM!A7="","-",EVM!A7) -> - | B38: CPI | C38: =EVM!H7 -> N/A | E38: =IF(AND(ISNUMBER(C38),ISNUMBER(D38)),C38-D38,"") | F38: =$B$3 -> 0.0001 | G38: =IF(D38="","PENDIENTE",IF(OR(ISTEXT(C38),ISTEXT(D38)),IF(AND(C38="N/A",D38="null"),"COINCIDE","DIFERENTE"),IF(ABS(C38-D38)<=F38,"COINCIDE","DIFERENTE"))) -> PENDIENTE
A39: =IF(EVM!A7="","-",EVM!A7) -> - | B39: SPI | C39: =EVM!I7 -> N/A | E39: =IF(AND(ISNUMBER(C39),ISNUMBER(D39)),C39-D39,"") | F39: =$B$3 -> 0.0001 | G39: =IF(D39="","PENDIENTE",IF(OR(ISTEXT(C39),ISTEXT(D39)),IF(AND(C39="N/A",D39="null"),"COINCIDE","DIFERENTE"),IF(ABS(C39-D39)<=F39,"COINCIDE","DIFERENTE"))) -> PENDIENTE
A40: =IF(EVM!A7="","-",EVM!A7) -> - | B40: EAC | C40: =EVM!J7 -> N/A | E40: =IF(AND(ISNUMBER(C40),ISNUMBER(D40)),C40-D40,"") | F40: =$B$2 -> 0.01 | G40: =IF(D40="","PENDIENTE",IF(OR(ISTEXT(C40),ISTEXT(D40)),IF(AND(C40="N/A",D40="null"),"COINCIDE","DIFERENTE"),IF(ABS(C40-D40)<=F40,"COINCIDE","DIFERENTE"))) -> PENDIENTE
A41: =IF(EVM!A7="","-",EVM!A7) -> - | B41: ETC | C41: =EVM!K7 -> N/A | E41: =IF(AND(ISNUMBER(C41),ISNUMBER(D41)),C41-D41,"") | F41: =$B$2 -> 0.01 | G41: =IF(D41="","PENDIENTE",IF(OR(ISTEXT(C41),ISTEXT(D41)),IF(AND(C41="N/A",D41="null"),"COINCIDE","DIFERENTE"),IF(ABS(C41-D41)<=F41,"COINCIDE","DIFERENTE"))) -> PENDIENTE
...
