Workbook

Sheet Datos
A1: Datos de entrada - Portal de clientes
A2: En azul los datos que se pueden cambiar
A3: Actividad | B3: BAC ($) | C3: % planificado | D3: % real | E3: AC ($)
A4: A. Diseño | B4: 20000000 | C4: 1 | D4: 1 | E4: 18000000
A5: B. Desarrollo | B5: 50000000 | C5: 0.6 | D5: 0.4 | E5: 25000000
A6: C. Pruebas | B6: 10000000 | C6: 0.2 | D6: 0.3 | E6: 2000000
A7: D. Despliegue | B7: 8000000 | C7: 0 | D7: 0 | E7: 0
A10: Tolerancias para comparar
A11: Índices (CPI, SPI) | B11: 0.0001 | C11: la API redondea a 4 decimales
A12: Dinero | B12: 0.01 | C12: la API redondea a 2 decimales

Sheet EVM
A1: Cálculo EVM
A2: N/A = división por cero (en la API sale null)
A3: Actividad | B3: BAC | C3: % plan | D3: % real | E3: AC | F3: PV | G3: EV | H3: CV | I3: SV | J3: CPI | K3: SPI | L3: EAC | M3: VAC | N3: Costo | O3: Cronograma | P3: Chequeo CPI | Q3: Chequeo SPI | R3: Chequeo VAC
A4: =Datos!A4 -> A. Diseño | B4: =Datos!B4 -> 20000000 | C4: =Datos!C4 -> 1 | D4: =Datos!D4 -> 1 | E4: =Datos!E4 -> 18000000 | F4: =C4*B4 -> 20000000 | G4: =D4*B4 -> 20000000 | H4: =G4-E4 -> 2000000 | I4: =G4-F4 -> 0 | J4: =IF(E4=0,"N/A",G4/E4) -> 1.1111111 | K4: =IF(F4=0,"N/A",G4/F4) -> 1 | L4: =IF(J4="N/A","N/A",IF(J4=0,"N/A",B4/J4)) -> 18000000 | M4: =IF(L4="N/A","N/A",B4-L4) -> 2000000 | N4: =IF(J4="N/A","No aplicable",IF(J4>1,"Bajo presupuesto",IF(J4<1,"Sobre presupuesto","En presupuesto"))) -> Bajo presupuesto | O4: =IF(K4="N/A","No aplicable",IF(K4>1,"Adelantada",IF(K4<1,"Atrasada","A tiempo"))) -> A tiempo | P4: =IF(J4="N/A","N/A",IF(SIGN(ROUND(H4,2))=SIGN(ROUND(J4-1,6)),"OK","REVISAR")) -> OK | Q4: =IF(K4="N/A","N/A",IF(SIGN(ROUND(I4,2))=SIGN(ROUND(K4-1,6)),"OK","REVISAR")) -> OK | R4: =IF(M4="N/A","N/A",IF(SIGN(ROUND(M4,2))=SIGN(ROUND(H4,2)),"OK","REVISAR")) -> OK
A5: =Datos!A5 -> B. Desarrollo | B5: =Datos!B5 -> 50000000 | C5: =Datos!C5 -> 0.6 | D5: =Datos!D5 -> 0.4 | E5: =Datos!E5 -> 25000000 | F5: =C5*B5 -> 30000000 | G5: =D5*B5 -> 20000000 | H5: =G5-E5 -> -5000000 | I5: =G5-F5 -> -10000000 | J5: =IF(E5=0,"N/A",G5/E5) -> 0.8 | K5: =IF(F5=0,"N/A",G5/F5) -> 0.66666667 | L5: =IF(J5="N/A","N/A",IF(J5=0,"N/A",B5/J5)) -> 62500000 | M5: =IF(L5="N/A","N/A",B5-L5) -> -12500000 | N5: =IF(J5="N/A","No aplicable",IF(J5>1,"Bajo presupuesto",IF(J5<1,"Sobre presupuesto","En presupuesto"))) -> Sobre presupuesto | O5: =IF(K5="N/A","No aplicable",IF(K5>1,"Adelantada",IF(K5<1,"Atrasada","A tiempo"))) -> Atrasada | P5: =IF(J5="N/A","N/A",IF(SIGN(ROUND(H5,2))=SIGN(ROUND(J5-1,6)),"OK","REVISAR")) -> OK | Q5: =IF(K5="N/A","N/A",IF(SIGN(ROUND(I5,2))=SIGN(ROUND(K5-1,6)),"OK","REVISAR")) -> OK | R5: =IF(M5="N/A","N/A",IF(SIGN(ROUND(M5,2))=SIGN(ROUND(H5,2)),"OK","REVISAR")) -> OK
A6: =Datos!A6 -> C. Pruebas | B6: =Datos!B6 -> 10000000 | C6: =Datos!C6 -> 0.2 | D6: =Datos!D6 -> 0.3 | E6: =Datos!E6 -> 2000000 | F6: =C6*B6 -> 2000000 | G6: =D6*B6 -> 3000000 | H6: =G6-E6 -> 1000000 | I6: =G6-F6 -> 1000000 | J6: =IF(E6=0,"N/A",G6/E6) -> 1.5 | K6: =IF(F6=0,"N/A",G6/F6) -> 1.5 | L6: =IF(J6="N/A","N/A",IF(J6=0,"N/A",B6/J6)) -> 6666666.7 | M6: =IF(L6="N/A","N/A",B6-L6) -> 3333333.3 | N6: =IF(J6="N/A","No aplicable",IF(J6>1,"Bajo presupuesto",IF(J6<1,"Sobre presupuesto","En presupuesto"))) -> Bajo presupuesto | O6: =IF(K6="N/A","No aplicable",IF(K6>1,"Adelantada",IF(K6<1,"Atrasada","A tiempo"))) -> Adelantada | P6: =IF(J6="N/A","N/A",IF(SIGN(ROUND(H6,2))=SIGN(ROUND(J6-1,6)),"OK","REVISAR")) -> OK | Q6: =IF(K6="N/A","N/A",IF(SIGN(ROUND(I6,2))=SIGN(ROUND(K6-1,6)),"OK","REVISAR")) -> OK | R6: =IF(M6="N/A","N/A",IF(SIGN(ROUND(M6,2))=SIGN(ROUND(H6,2)),"OK","REVISAR")) -> OK
A7: =Datos!A7 -> D. Despliegue | B7: =Datos!B7 -> 8000000 | C7: =Datos!C7 -> 0 | D7: =Datos!D7 -> 0 | E7: =Datos!E7 -> 0 | F7: =C7*B7 -> 0 | G7: =D7*B7 -> 0 | H7: =G7-E7 -> 0 | I7: =G7-F7 -> 0 | J7: =IF(E7=0,"N/A",G7/E7) -> N/A | K7: =IF(F7=0,"N/A",G7/F7) -> N/A | L7: =IF(J7="N/A","N/A",IF(J7=0,"N/A",B7/J7)) -> N/A | M7: =IF(L7="N/A","N/A",B7-L7) -> N/A | N7: =IF(J7="N/A","No aplicable",IF(J7>1,"Bajo presupuesto",IF(J7<1,"Sobre presupuesto","En presupuesto"))) -> No aplicable | O7: =IF(K7="N/A","No aplicable",IF(K7>1,"Adelantada",IF(K7<1,"Atrasada","A tiempo"))) -> No aplicable | P7: =IF(J7="N/A","N/A",IF(SIGN(ROUND(H7,2))=SIGN(ROUND(J7-1,6)),"OK","REVISAR")) -> N/A | Q7: =IF(K7="N/A","N/A",IF(SIGN(ROUND(I7,2))=SIGN(ROUND(K7-1,6)),"OK","REVISAR")) -> N/A | R7: =IF(M7="N/A","N/A",IF(SIGN(ROUND(M7,2))=SIGN(ROUND(H7,2)),"OK","REVISAR")) -> N/A
A8: Total proyecto | B8: =SUM(B4:B7) -> 88000000 | C8: =IF(B8=0,"N/A",F8/B8) -> 0.59090909 | D8: =IF(B8=0,"N/A",G8/B8) -> 0.48863636 | E8: =SUM(E4:E7) -> 45000000 | F8: =SUM(F4:F7) -> 52000000 | G8: =SUM(G4:G7) -> 43000000 | H8: =G8-E8 -> -2000000 | I8: =G8-F8 -> -9000000 | J8: =IF(E8=0,"N/A",G8/E8) -> 0.95555556 | K8: =IF(F8=0,"N/A",G8/F8) -> 0.82692308 | L8: =IF(J8="N/A","N/A",IF(J8=0,"N/A",B8/J8)) -> 92093023 | M8: =IF(L8="N/A","N/A",B8-L8) -> -4093023.3 | N8: =IF(J8="N/A","No aplicable",IF(J8>1,"Bajo presupuesto",IF(J8<1,"Sobre presupuesto","En presupuesto"))) -> Sobre presupuesto | O8: =IF(K8="N/A","No aplicable",IF(K8>1,"Adelantado",IF(K8<1,"Atrasado","A tiempo"))) -> Atrasado | P8: =IF(J8="N/A","N/A",IF(SIGN(ROUND(H8,2))=SIGN(ROUND(J8-1,6)),"OK","REVISAR")) -> OK | Q8: =IF(K8="N/A","N/A",IF(SIGN(ROUND(I8,2))=SIGN(ROUND(K8-1,6)),"OK","REVISAR")) -> OK | R8: =IF(M8="N/A","N/A",IF(SIGN(ROUND(M8,2))=SIGN(ROUND(H8,2)),"OK","REVISAR")) -> OK
A11: Chequeos del total
A12: Promedio CPI de las actividades | B12: =AVERAGE(J4:J7) -> 1.137037
A13: CPI total (EV/AC) | B13: =J8 -> 0.95555556
A14: Diferencia | B14: =B12-B13 -> 0.18148148
A15: Promedio SPI de las actividades | B15: =AVERAGE(K4:K7) -> 1.0555556
A16: SPI total (EV/PV) | B16: =K8 -> 0.82692308
A17: Suma EAC actividades (sin D) | B17: =SUM(L4:L7) -> 87166667
A18: Suma EAC + BAC de D | B18: =B17+SUMIF(L4:L7,"N/A",B4:B7) -> 95166667
A19: EAC total | B19: =L8 -> 92093023
A20: Suma VAC actividades | B20: =SUM(M4:M7) -> -7166666.7
A21: VAC total | B21: =M8 -> -4093023.3

Sheet Comparación API
A1: Excel vs API
A2: Pegar en la columna D lo que devuelve la API (si viene null, escribir null)
A3: OK: | B3: =COUNTIF(H6:H45,"OK") -> 0 | C3: Diferencias: | D3: =COUNTIF(H6:H45,"DIFERENCIA") -> 0 | E3: Pendientes: | F3: =COUNTIF(H6:H45,"PENDIENTE") -> 40
A5: Entidad | B5: Indicador | C5: Excel | D5: API | E5: API (número) | F5: Diferencia | G5: Tolerancia | H5: Estado | I5: Posible causa
A6: A. Diseño | B6: PV | C6: =EVM!F4 -> 20000000 | E6: =IF(D6="","",IF(ISNUMBER(D6),D6,IFERROR(VALUE(SUBSTITUTE(D6,".",MID(1/2,2,1))),IF(OR(UPPER(D6)="NULL",UPPER(D6)="N/A"),"null","TEXTO")))) | F6: =IF(AND(ISNUMBER(C6),ISNUMBER(E6)),E6-C6,"") | G6: =Datos!$B$12 -> 0.01 | H6: =IF(D6="","PENDIENTE",IF(ISNUMBER(C6),IF(ISNUMBER(E6),IF(ABS(F6)<=G6,"OK","DIFERENCIA"),"DIFERENCIA"),IF(E6="null","OK","DIFERENCIA"))) -> PENDIENTE | I6: =IF(H6<>"DIFERENCIA","",IF(AND(ISNUMBER(C6),E6="null"),"API da null y debería dar valor",IF(AND(NOT(ISNUMBER(C6)),ISNUMBER(E6)),"API da número y debería dar null",IF(E6="TEXTO","formato raro en la API",IF(IFERROR(ABS(E6-(C6*100))<=G6,FALSE()),"% como entero (60 en vez de 0,6)?",IF(IFERROR(ABS(F6)<=1,FALSE()),"redondeo","revisar"))))))
A7: A. Diseño | B7: EV | C7: =EVM!G4 -> 20000000 | E7: =IF(D7="","",IF(ISNUMBER(D7),D7,IFERROR(VALUE(SUBSTITUTE(D7,".",MID(1/2,2,1))),IF(OR(UPPER(D7)="NULL",UPPER(D7)="N/A"),"null","TEXTO")))) | F7: =IF(AND(ISNUMBER(C7),ISNUMBER(E7)),E7-C7,"") | G7: =Datos!$B$12 -> 0.01 | H7: =IF(D7="","PENDIENTE",IF(ISNUMBER(C7),IF(ISNUMBER(E7),IF(ABS(F7)<=G7,"OK","DIFERENCIA"),"DIFERENCIA"),IF(E7="null","OK","DIFERENCIA"))) -> PENDIENTE | I7: =IF(H7<>"DIFERENCIA","",IF(AND(ISNUMBER(C7),E7="null"),"API da null y debería dar valor",IF(AND(NOT(ISNUMBER(C7)),ISNUMBER(E7)),"API da número y debería dar null",IF(E7="TEXTO","formato raro en la API",IF(IFERROR(ABS(E7-(C7*100))<=G7,FALSE()),"% como entero (60 en vez de 0,6)?",IF(IFERROR(ABS(F7)<=1,FALSE()),"redondeo","revisar"))))))
A8: A. Diseño | B8: CV | C8: =EVM!H4 -> 2000000 | E8: =IF(D8="","",IF(ISNUMBER(D8),D8,IFERROR(VALUE(SUBSTITUTE(D8,".",MID(1/2,2,1))),IF(OR(UPPER(D8)="NULL",UPPER(D8)="N/A"),"null","TEXTO")))) | F8: =IF(AND(ISNUMBER(C8),ISNUMBER(E8)),E8-C8,"") | G8: =Datos!$B$12 -> 0.01 | H8: =IF(D8="","PENDIENTE",IF(ISNUMBER(C8),IF(ISNUMBER(E8),IF(ABS(F8)<=G8,"OK","DIFERENCIA"),"DIFERENCIA"),IF(E8="null","OK","DIFERENCIA"))) -> PENDIENTE | I8: =IF(H8<>"DIFERENCIA","",IF(AND(ISNUMBER(C8),E8="null"),"API da null y debería dar valor",IF(AND(NOT(ISNUMBER(C8)),ISNUMBER(E8)),"API da número y debería dar null",IF(E8="TEXTO","formato raro en la API",IF(IFERROR(ABS(E8-(C8*100))<=G8,FALSE()),"% como entero (60 en vez de 0,6)?",IF(IFERROR(ABS(F8)<=1,FALSE()),"redondeo","revisar"))))))
A9: A. Diseño | B9: SV | C9: =EVM!I4 -> 0 | E9: =IF(D9="","",IF(ISNUMBER(D9),D9,IFERROR(VALUE(SUBSTITUTE(D9,".",MID(1/2,2,1))),IF(OR(UPPER(D9)="NULL",UPPER(D9)="N/A"),"null","TEXTO")))) | F9: =IF(AND(ISNUMBER(C9),ISNUMBER(E9)),E9-C9,"") | G9: =Datos!$B$12 -> 0.01 | H9: =IF(D9="","PENDIENTE",IF(ISNUMBER(C9),IF(ISNUMBER(E9),IF(ABS(F9)<=G9,"OK","DIFERENCIA"),"DIFERENCIA"),IF(E9="null","OK","DIFERENCIA"))) -> PENDIENTE | I9: =IF(H9<>"DIFERENCIA","",IF(AND(ISNUMBER(C9),E9="null"),"API da null y debería dar valor",IF(AND(NOT(ISNUMBER(C9)),ISNUMBER(E9)),"API da número y debería dar null",IF(E9="TEXTO","formato raro en la API",IF(IFERROR(ABS(E9-(C9*100))<=G9,FALSE()),"% como entero (60 en vez de 0,6)?",IF(IFERROR(ABS(F9)<=1,FALSE()),"redondeo","revisar"))))))
A10: A. Diseño | B10: CPI | C10: =EVM!J4 -> 1.1111111 | E10: =IF(D10="","",IF(ISNUMBER(D10),D10,IFERROR(VALUE(SUBSTITUTE(D10,".",MID(1/2,2,1))),IF(OR(UPPER(D10)="NULL",UPPER(D10)="N/A"),"null","TEXTO")))) | F10: =IF(AND(ISNUMBER(C10),ISNUMBER(E10)),E10-C10,"") | G10: =Datos!$B$11 -> 0.0001 | H10: =IF(D10="","PENDIENTE",IF(ISNUMBER(C10),IF(ISNUMBER(E10),IF(ABS(F10)<=G10,"OK","DIFERENCIA"),"DIFERENCIA"),IF(E10="null","OK","DIFERENCIA"))) -> PENDIENTE | I10: =IF(H10<>"DIFERENCIA","",IF(AND(ISNUMBER(C10),E10="null"),"API da null y debería dar valor",IF(AND(NOT(ISNUMBER(C10)),ISNUMBER(E10)),"API da número y debería dar null",IF(E10="TEXTO","formato raro en la API",IF(IFERROR(ABS(E10-(C10*100))<=G10,FALSE()),"% como entero (60 en vez de 0,6)?",IF(IFERROR(ABS(F10)<=1,FALSE()),"redondeo","revisar"))))))
A11: A. Diseño | B11: SPI | C11: =EVM!K4 -> 1 | E11: =IF(D11="","",IF(ISNUMBER(D11),D11,IFERROR(VALUE(SUBSTITUTE(D11,".",MID(1/2,2,1))),IF(OR(UPPER(D11)="NULL",UPPER(D11)="N/A"),"null","TEXTO")))) | F11: =IF(AND(ISNUMBER(C11),ISNUMBER(E11)),E11-C11,"") | G11: =Datos!$B$11 -> 0.0001 | H11: =IF(D11="","PENDIENTE",IF(ISNUMBER(C11),IF(ISNUMBER(E11),IF(ABS(F11)<=G11,"OK","DIFERENCIA"),"DIFERENCIA"),IF(E11="null","OK","DIFERENCIA"))) -> PENDIENTE | I11: =IF(H11<>"DIFERENCIA","",IF(AND(ISNUMBER(C11),E11="null"),"API da null y debería dar valor",IF(AND(NOT(ISNUMBER(C11)),ISNUMBER(E11)),"API da número y debería dar null",IF(E11="TEXTO","formato raro en la API",IF(IFERROR(ABS(E11-(C11*100))<=G11,FALSE()),"% como entero (60 en vez de 0,6)?",IF(IFERROR(ABS(F11)<=1,FALSE()),"redondeo","revisar"))))))
A12: A. Diseño | B12: EAC | C12: =EVM!L4 -> 18000000 | E12: =IF(D12="","",IF(ISNUMBER(D12),D12,IFERROR(VALUE(SUBSTITUTE(D12,".",MID(1/2,2,1))),IF(OR(UPPER(D12)="NULL",UPPER(D12)="N/A"),"null","TEXTO")))) | F12: =IF(AND(ISNUMBER(C12),ISNUMBER(E12)),E12-C12,"") | G12: =Datos!$B$12 -> 0.01 | H12: =IF(D12="","PENDIENTE",IF(ISNUMBER(C12),IF(ISNUMBER(E12),IF(ABS(F12)<=G12,"OK","DIFERENCIA"),"DIFERENCIA"),IF(E12="null","OK","DIFERENCIA"))) -> PENDIENTE | I12: =IF(H12<>"DIFERENCIA","",IF(AND(ISNUMBER(C12),E12="null"),"API da null y debería dar valor",IF(AND(NOT(ISNUMBER(C12)),ISNUMBER(E12)),"API da número y debería dar null",IF(E12="TEXTO","formato raro en la API",IF(IFERROR(ABS(E12-(C12*100))<=G12,FALSE()),"% como entero (60 en vez de 0,6)?",IF(IFERROR(ABS(F12)<=1,FALSE()),"redondeo","revisar"))))))
A13: A. Diseño | B13: VAC | C13: =EVM!M4 -> 2000000 | E13: =IF(D13="","",IF(ISNUMBER(D13),D13,IFERROR(VALUE(SUBSTITUTE(D13,".",MID(1/2,2,1))),IF(OR(UPPER(D13)="NULL",UPPER(D13)="N/A"),"null","TEXTO")))) | F13: =IF(AND(ISNUMBER(C13),ISNUMBER(E13)),E13-C13,"") | G13: =Datos!$B$12 -> 0.01 | H13: =IF(D13="","PENDIENTE",IF(ISNUMBER(C13),IF(ISNUMBER(E13),IF(ABS(F13)<=G13,"OK","DIFERENCIA"),"DIFERENCIA"),IF(E13="null","OK","DIFERENCIA"))) -> PENDIENTE | I13: =IF(H13<>"DIFERENCIA","",IF(AND(ISNUMBER(C13),E13="null"),"API da null y debería dar valor",IF(AND(NOT(ISNUMBER(C13)),ISNUMBER(E13)),"API da número y debería dar null",IF(E13="TEXTO","formato raro en la API",IF(IFERROR(ABS(E13-(C13*100))<=G13,FALSE()),"% como entero (60 en vez de 0,6)?",IF(IFERROR(ABS(F13)<=1,FALSE()),"redondeo","revisar"))))))
A14: B. Desarrollo | B14: PV | C14: =EVM!F5 -> 30000000 | E14: =IF(D14="","",IF(ISNUMBER(D14),D14,IFERROR(VALUE(SUBSTITUTE(D14,".",MID(1/2,2,1))),IF(OR(UPPER(D14)="NULL",UPPER(D14)="N/A"),"null","TEXTO")))) | F14: =IF(AND(ISNUMBER(C14),ISNUMBER(E14)),E14-C14,"") | G14: =Datos!$B$12 -> 0.01 | H14: =IF(D14="","PENDIENTE",IF(ISNUMBER(C14),IF(ISNUMBER(E14),IF(ABS(F14)<=G14,"OK","DIFERENCIA"),"DIFERENCIA"),IF(E14="null","OK","DIFERENCIA"))) -> PENDIENTE | I14: =IF(H14<>"DIFERENCIA","",IF(AND(ISNUMBER(C14),E14="null"),"API da null y debería dar valor",IF(AND(NOT(ISNUMBER(C14)),ISNUMBER(E14)),"API da número y debería dar null",IF(E14="TEXTO","formato raro en la API",IF(IFERROR(ABS(E14-(C14*100))<=G14,FALSE()),"% como entero (60 en vez de 0,6)?",IF(IFERROR(ABS(F14)<=1,FALSE()),"redondeo","revisar"))))))
A15: B. Desarrollo | B15: EV | C15: =EVM!G5 -> 20000000 | E15: =IF(D15="","",IF(ISNUMBER(D15),D15,IFERROR(VALUE(SUBSTITUTE(D15,".",MID(1/2,2,1))),IF(OR(UPPER(D15)="NULL",UPPER(D15)="N/A"),"null","TEXTO")))) | F15: =IF(AND(ISNUMBER(C15),ISNUMBER(E15)),E15-C15,"") | G15: =Datos!$B$12 -> 0.01 | H15: =IF(D15="","PENDIENTE",IF(ISNUMBER(C15),IF(ISNUMBER(E15),IF(ABS(F15)<=G15,"OK","DIFERENCIA"),"DIFERENCIA"),IF(E15="null","OK","DIFERENCIA"))) -> PENDIENTE | I15: =IF(H15<>"DIFERENCIA","",IF(AND(ISNUMBER(C15),E15="null"),"API da null y debería dar valor",IF(AND(NOT(ISNUMBER(C15)),ISNUMBER(E15)),"API da número y debería dar null",IF(E15="TEXTO","formato raro en la API",IF(IFERROR(ABS(E15-(C15*100))<=G15,FALSE()),"% como entero (60 en vez de 0,6)?",IF(IFERROR(ABS(F15)<=1,FALSE()),"redondeo","revisar"))))))
A16: B. Desarrollo | B16: CV | C16: =EVM!H5 -> -5000000 | E16: =IF(D16="","",IF(ISNUMBER(D16),D16,IFERROR(VALUE(SUBSTITUTE(D16,".",MID(1/2,2,1))),IF(OR(UPPER(D16)="NULL",UPPER(D16)="N/A"),"null","TEXTO")))) | F16: =IF(AND(ISNUMBER(C16),ISNUMBER(E16)),E16-C16,"") | G16: =Datos!$B$12 -> 0.01 | H16: =IF(D16="","PENDIENTE",IF(ISNUMBER(C16),IF(ISNUMBER(E16),IF(ABS(F16)<=G16,"OK","DIFERENCIA"),"DIFERENCIA"),IF(E16="null","OK","DIFERENCIA"))) -> PENDIENTE | I16: =IF(H16<>"DIFERENCIA","",IF(AND(ISNUMBER(C16),E16="null"),"API da null y debería dar valor",IF(AND(NOT(ISNUMBER(C16)),ISNUMBER(E16)),"API da número y debería dar null",IF(E16="TEXTO","formato raro en la API",IF(IFERROR(ABS(E16-(C16*100))<=G16,FALSE()),"% como entero (60 en vez de 0,6)?",IF(IFERROR(ABS(F16)<=1,FALSE()),"redondeo","revisar"))))))
A17: B. Desarrollo | B17: SV | C17: =EVM!I5 -> -10000000 | E17: =IF(D17="","",IF(ISNUMBER(D17),D17,IFERROR(VALUE(SUBSTITUTE(D17,".",MID(1/2,2,1))),IF(OR(UPPER(D17)="NULL",UPPER(D17)="N/A"),"null","TEXTO")))) | F17: =IF(AND(ISNUMBER(C17),ISNUMBER(E17)),E17-C17,"") | G17: =Datos!$B$12 -> 0.01 | H17: =IF(D17="","PENDIENTE",IF(ISNUMBER(C17),IF(ISNUMBER(E17),IF(ABS(F17)<=G17,"OK","DIFERENCIA"),"DIFERENCIA"),IF(E17="null","OK","DIFERENCIA"))) -> PENDIENTE | I17: =IF(H17<>"DIFERENCIA","",IF(AND(ISNUMBER(C17),E17="null"),"API da null y debería dar valor",IF(AND(NOT(ISNUMBER(C17)),ISNUMBER(E17)),"API da número y debería dar null",IF(E17="TEXTO","formato raro en la API",IF(IFERROR(ABS(E17-(C17*100))<=G17,FALSE()),"% como entero (60 en vez de 0,6)?",IF(IFERROR(ABS(F17)<=1,FALSE()),"redondeo","revisar"))))))
A18: B. Desarrollo | B18: CPI | C18: =EVM!J5 -> 0.8 | E18: =IF(D18="","",IF(ISNUMBER(D18),D18,IFERROR(VALUE(SUBSTITUTE(D18,".",MID(1/2,2,1))),IF(OR(UPPER(D18)="NULL",UPPER(D18)="N/A"),"null","TEXTO")))) | F18: =IF(AND(ISNUMBER(C18),ISNUMBER(E18)),E18-C18,"") | G18: =Datos!$B$11 -> 0.0001 | H18: =IF(D18="","PENDIENTE",IF(ISNUMBER(C18),IF(ISNUMBER(E18),IF(ABS(F18)<=G18,"OK","DIFERENCIA"),"DIFERENCIA"),IF(E18="null","OK","DIFERENCIA"))) -> PENDIENTE | I18: =IF(H18<>"DIFERENCIA","",IF(AND(ISNUMBER(C18),E18="null"),"API da null y debería dar valor",IF(AND(NOT(ISNUMBER(C18)),ISNUMBER(E18)),"API da número y debería dar null",IF(E18="TEXTO","formato raro en la API",IF(IFERROR(ABS(E18-(C18*100))<=G18,FALSE()),"% como entero (60 en vez de 0,6)?",IF(IFERROR(ABS(F18)<=1,FALSE()),"redondeo","revisar"))))))
A19: B. Desarrollo | B19: SPI | C19: =EVM!K5 -> 0.66666667 | E19: =IF(D19="","",IF(ISNUMBER(D19),D19,IFERROR(VALUE(SUBSTITUTE(D19,".",MID(1/2,2,1))),IF(OR(UPPER(D19)="NULL",UPPER(D19)="N/A"),"null","TEXTO")))) | F19: =IF(AND(ISNUMBER(C19),ISNUMBER(E19)),E19-C19,"") | G19: =Datos!$B$11 -> 0.0001 | H19: =IF(D19="","PENDIENTE",IF(ISNUMBER(C19),IF(ISNUMBER(E19),IF(ABS(F19)<=G19,"OK","DIFERENCIA"),"DIFERENCIA"),IF(E19="null","OK","DIFERENCIA"))) -> PENDIENTE | I19: =IF(H19<>"DIFERENCIA","",IF(AND(ISNUMBER(C19),E19="null"),"API da null y debería dar valor",IF(AND(NOT(ISNUMBER(C19)),ISNUMBER(E19)),"API da número y debería dar null",IF(E19="TEXTO","formato raro en la API",IF(IFERROR(ABS(E19-(C19*100))<=G19,FALSE()),"% como entero (60 en vez de 0,6)?",IF(IFERROR(ABS(F19)<=1,FALSE()),"redondeo","revisar"))))))
A20: B. Desarrollo | B20: EAC | C20: =EVM!L5 -> 62500000 | E20: =IF(D20="","",IF(ISNUMBER(D20),D20,IFERROR(VALUE(SUBSTITUTE(D20,".",MID(1/2,2,1))),IF(OR(UPPER(D20)="NULL",UPPER(D20)="N/A"),"null","TEXTO")))) | F20: =IF(AND(ISNUMBER(C20),ISNUMBER(E20)),E20-C20,"") | G20: =Datos!$B$12 -> 0.01 | H20: =IF(D20="","PENDIENTE",IF(ISNUMBER(C20),IF(ISNUMBER(E20),IF(ABS(F20)<=G20,"OK","DIFERENCIA"),"DIFERENCIA"),IF(E20="null","OK","DIFERENCIA"))) -> PENDIENTE | I20: =IF(H20<>"DIFERENCIA","",IF(AND(ISNUMBER(C20),E20="null"),"API da null y debería dar valor",IF(AND(NOT(ISNUMBER(C20)),ISNUMBER(E20)),"API da número y debería dar null",IF(E20="TEXTO","formato raro en la API",IF(IFERROR(ABS(E20-(C20*100))<=G20,FALSE()),"% como entero (60 en vez de 0,6)?",IF(IFERROR(ABS(F20)<=1,FALSE()),"redondeo","revisar"))))))
A21: B. Desarrollo | B21: VAC | C21: =EVM!M5 -> -12500000 | E21: =IF(D21="","",IF(ISNUMBER(D21),D21,IFERROR(VALUE(SUBSTITUTE(D21,".",MID(1/2,2,1))),IF(OR(UPPER(D21)="NULL",UPPER(D21)="N/A"),"null","TEXTO")))) | F21: =IF(AND(ISNUMBER(C21),ISNUMBER(E21)),E21-C21,"") | G21: =Datos!$B$12 -> 0.01 | H21: =IF(D21="","PENDIENTE",IF(ISNUMBER(C21),IF(ISNUMBER(E21),IF(ABS(F21)<=G21,"OK","DIFERENCIA"),"DIFERENCIA"),IF(E21="null","OK","DIFERENCIA"))) -> PENDIENTE | I21: =IF(H21<>"DIFERENCIA","",IF(AND(ISNUMBER(C21),E21="null"),"API da null y debería dar valor",IF(AND(NOT(ISNUMBER(C21)),ISNUMBER(E21)),"API da número y debería dar null",IF(E21="TEXTO","formato raro en la API",IF(IFERROR(ABS(E21-(C21*100))<=G21,FALSE()),"% como entero (60 en vez de 0,6)?",IF(IFERROR(ABS(F21)<=1,FALSE()),"redondeo","revisar"))))))
A22: C. Pruebas | B22: PV | C22: =EVM!F6 -> 2000000 | E22: =IF(D22="","",IF(ISNUMBER(D22),D22,IFERROR(VALUE(SUBSTITUTE(D22,".",MID(1/2,2,1))),IF(OR(UPPER(D22)="NULL",UPPER(D22)="N/A"),"null","TEXTO")))) | F22: =IF(AND(ISNUMBER(C22),ISNUMBER(E22)),E22-C22,"") | G22: =Datos!$B$12 -> 0.01 | H22: =IF(D22="","PENDIENTE",IF(ISNUMBER(C22),IF(ISNUMBER(E22),IF(ABS(F22)<=G22,"OK","DIFERENCIA"),"DIFERENCIA"),IF(E22="null","OK","DIFERENCIA"))) -> PENDIENTE | I22: =IF(H22<>"DIFERENCIA","",IF(AND(ISNUMBER(C22),E22="null"),"API da null y debería dar valor",IF(AND(NOT(ISNUMBER(C22)),ISNUMBER(E22)),"API da número y debería dar null",IF(E22="TEXTO","formato raro en la API",IF(IFERROR(ABS(E22-(C22*100))<=G22,FALSE()),"% como entero (60 en vez de 0,6)?",IF(IFERROR(ABS(F22)<=1,FALSE()),"redondeo","revisar"))))))
A23: C. Pruebas | B23: EV | C23: =EVM!G6 -> 3000000 | E23: =IF(D23="","",IF(ISNUMBER(D23),D23,IFERROR(VALUE(SUBSTITUTE(D23,".",MID(1/2,2,1))),IF(OR(UPPER(D23)="NULL",UPPER(D23)="N/A"),"null","TEXTO")))) | F23: =IF(AND(ISNUMBER(C23),ISNUMBER(E23)),E23-C23,"") | G23: =Datos!$B$12 -> 0.01 | H23: =IF(D23="","PENDIENTE",IF(ISNUMBER(C23),IF(ISNUMBER(E23),IF(ABS(F23)<=G23,"OK","DIFERENCIA"),"DIFERENCIA"),IF(E23="null","OK","DIFERENCIA"))) -> PENDIENTE | I23: =IF(H23<>"DIFERENCIA","",IF(AND(ISNUMBER(C23),E23="null"),"API da null y debería dar valor",IF(AND(NOT(ISNUMBER(C23)),ISNUMBER(E23)),"API da número y debería dar null",IF(E23="TEXTO","formato raro en la API",IF(IFERROR(ABS(E23-(C23*100))<=G23,FALSE()),"% como entero (60 en vez de 0,6)?",IF(IFERROR(ABS(F23)<=1,FALSE()),"redondeo","revisar"))))))
A24: C. Pruebas | B24: CV | C24: =EVM!H6 -> 1000000 | E24: =IF(D24="","",IF(ISNUMBER(D24),D24,IFERROR(VALUE(SUBSTITUTE(D24,".",MID(1/2,2,1))),IF(OR(UPPER(D24)="NULL",UPPER(D24)="N/A"),"null","TEXTO")))) | F24: =IF(AND(ISNUMBER(C24),ISNUMBER(E24)),E24-C24,"") | G24: =Datos!$B$12 -> 0.01 | H24: =IF(D24="","PENDIENTE",IF(ISNUMBER(C24),IF(ISNUMBER(E24),IF(ABS(F24)<=G24,"OK","DIFERENCIA"),"DIFERENCIA"),IF(E24="null","OK","DIFERENCIA"))) -> PENDIENTE | I24: =IF(H24<>"DIFERENCIA","",IF(AND(ISNUMBER(C24),E24="null"),"API da null y debería dar valor",IF(AND(NOT(ISNUMBER(C24)),ISNUMBER(E24)),"API da número y debería dar null",IF(E24="TEXTO","formato raro en la API",IF(IFERROR(ABS(E24-(C24*100))<=G24,FALSE()),"% como entero (60 en vez de 0,6)?",IF(IFERROR(ABS(F24)<=1,FALSE()),"redondeo","revisar"))))))
A25: C. Pruebas | B25: SV | C25: =EVM!I6 -> 1000000 | E25: =IF(D25="","",IF(ISNUMBER(D25),D25,IFERROR(VALUE(SUBSTITUTE(D25,".",MID(1/2,2,1))),IF(OR(UPPER(D25)="NULL",UPPER(D25)="N/A"),"null","TEXTO")))) | F25: =IF(AND(ISNUMBER(C25),ISNUMBER(E25)),E25-C25,"") | G25: =Datos!$B$12 -> 0.01 | H25: =IF(D25="","PENDIENTE",IF(ISNUMBER(C25),IF(ISNUMBER(E25),IF(ABS(F25)<=G25,"OK","DIFERENCIA"),"DIFERENCIA"),IF(E25="null","OK","DIFERENCIA"))) -> PENDIENTE | I25: =IF(H25<>"DIFERENCIA","",IF(AND(ISNUMBER(C25),E25="null"),"API da null y debería dar valor",IF(AND(NOT(ISNUMBER(C25)),ISNUMBER(E25)),"API da número y debería dar null",IF(E25="TEXTO","formato raro en la API",IF(IFERROR(ABS(E25-(C25*100))<=G25,FALSE()),"% como entero (60 en vez de 0,6)?",IF(IFERROR(ABS(F25)<=1,FALSE()),"redondeo","revisar"))))))
A26: C. Pruebas | B26: CPI | C26: =EVM!J6 -> 1.5 | E26: =IF(D26="","",IF(ISNUMBER(D26),D26,IFERROR(VALUE(SUBSTITUTE(D26,".",MID(1/2,2,1))),IF(OR(UPPER(D26)="NULL",UPPER(D26)="N/A"),"null","TEXTO")))) | F26: =IF(AND(ISNUMBER(C26),ISNUMBER(E26)),E26-C26,"") | G26: =Datos!$B$11 -> 0.0001 | H26: =IF(D26="","PENDIENTE",IF(ISNUMBER(C26),IF(ISNUMBER(E26),IF(ABS(F26)<=G26,"OK","DIFERENCIA"),"DIFERENCIA"),IF(E26="null","OK","DIFERENCIA"))) -> PENDIENTE | I26: =IF(H26<>"DIFERENCIA","",IF(AND(ISNUMBER(C26),E26="null"),"API da null y debería dar valor",IF(AND(NOT(ISNUMBER(C26)),ISNUMBER(E26)),"API da número y debería dar null",IF(E26="TEXTO","formato raro en la API",IF(IFERROR(ABS(E26-(C26*100))<=G26,FALSE()),"% como entero (60 en vez de 0,6)?",IF(IFERROR(ABS(F26)<=1,FALSE()),"redondeo","revisar"))))))
A27: C. Pruebas | B27: SPI | C27: =EVM!K6 -> 1.5 | E27: =IF(D27="","",IF(ISNUMBER(D27),D27,IFERROR(VALUE(SUBSTITUTE(D27,".",MID(1/2,2,1))),IF(OR(UPPER(D27)="NULL",UPPER(D27)="N/A"),"null","TEXTO")))) | F27: =IF(AND(ISNUMBER(C27),ISNUMBER(E27)),E27-C27,"") | G27: =Datos!$B$11 -> 0.0001 | H27: =IF(D27="","PENDIENTE",IF(ISNUMBER(C27),IF(ISNUMBER(E27),IF(ABS(F27)<=G27,"OK","DIFERENCIA"),"DIFERENCIA"),IF(E27="null","OK","DIFERENCIA"))) -> PENDIENTE | I27: =IF(H27<>"DIFERENCIA","",IF(AND(ISNUMBER(C27),E27="null"),"API da null y debería dar valor",IF(AND(NOT(ISNUMBER(C27)),ISNUMBER(E27)),"API da número y debería dar null",IF(E27="TEXTO","formato raro en la API",IF(IFERROR(ABS(E27-(C27*100))<=G27,FALSE()),"% como entero (60 en vez de 0,6)?",IF(IFERROR(ABS(F27)<=1,FALSE()),"redondeo","revisar"))))))
A28: C. Pruebas | B28: EAC | C28: =EVM!L6 -> 6666666.7 | E28: =IF(D28="","",IF(ISNUMBER(D28),D28,IFERROR(VALUE(SUBSTITUTE(D28,".",MID(1/2,2,1))),IF(OR(UPPER(D28)="NULL",UPPER(D28)="N/A"),"null","TEXTO")))) | F28: =IF(AND(ISNUMBER(C28),ISNUMBER(E28)),E28-C28,"") | G28: =Datos!$B$12 -> 0.01 | H28: =IF(D28="","PENDIENTE",IF(ISNUMBER(C28),IF(ISNUMBER(E28),IF(ABS(F28)<=G28,"OK","DIFERENCIA"),"DIFERENCIA"),IF(E28="null","OK","DIFERENCIA"))) -> PENDIENTE | I28: =IF(H28<>"DIFERENCIA","",IF(AND(ISNUMBER(C28),E28="null"),"API da null y debería dar valor",IF(AND(NOT(ISNUMBER(C28)),ISNUMBER(E28)),"API da número y debería dar null",IF(E28="TEXTO","formato raro en la API",IF(IFERROR(ABS(E28-(C28*100))<=G28,FALSE()),"% como entero (60 en vez de 0,6)?",IF(IFERROR(ABS(F28)<=1,FALSE()),"redondeo","revisar"))))))
A29: C. Pruebas | B29: VAC | C29: =EVM!M6 -> 3333333.3 | E29: =IF(D29="","",IF(ISNUMBER(D29),D29,IFERROR(VALUE(SUBSTITUTE(D29,".",MID(1/2,2,1))),IF(OR(UPPER(D29)="NULL",UPPER(D29)="N/A"),"null","TEXTO")))) | F29: =IF(AND(ISNUMBER(C29),ISNUMBER(E29)),E29-C29,"") | G29: =Datos!$B$12 -> 0.01 | H29: =IF(D29="","PENDIENTE",IF(ISNUMBER(C29),IF(ISNUMBER(E29),IF(ABS(F29)<=G29,"OK","DIFERENCIA"),"DIFERENCIA"),IF(E29="null","OK","DIFERENCIA"))) -> PENDIENTE | I29: =IF(H29<>"DIFERENCIA","",IF(AND(ISNUMBER(C29),E29="null"),"API da null y debería dar valor",IF(AND(NOT(ISNUMBER(C29)),ISNUMBER(E29)),"API da número y debería dar null",IF(E29="TEXTO","formato raro en la API",IF(IFERROR(ABS(E29-(C29*100))<=G29,FALSE()),"% como entero (60 en vez de 0,6)?",IF(IFERROR(ABS(F29)<=1,FALSE()),"redondeo","revisar"))))))
A30: D. Despliegue | B30: PV | C30: =EVM!F7 -> 0 | E30: =IF(D30="","",IF(ISNUMBER(D30),D30,IFERROR(VALUE(SUBSTITUTE(D30,".",MID(1/2,2,1))),IF(OR(UPPER(D30)="NULL",UPPER(D30)="N/A"),"null","TEXTO")))) | F30: =IF(AND(ISNUMBER(C30),ISNUMBER(E30)),E30-C30,"") | G30: =Datos!$B$12 -> 0.01 | H30: =IF(D30="","PENDIENTE",IF(ISNUMBER(C30),IF(ISNUMBER(E30),IF(ABS(F30)<=G30,"OK","DIFERENCIA"),"DIFERENCIA"),IF(E30="null","OK","DIFERENCIA"))) -> PENDIENTE | I30: =IF(H30<>"DIFERENCIA","",IF(AND(ISNUMBER(C30),E30="null"),"API da null y debería dar valor",IF(AND(NOT(ISNUMBER(C30)),ISNUMBER(E30)),"API da número y debería dar null",IF(E30="TEXTO","formato raro en la API",IF(IFERROR(ABS(E30-(C30*100))<=G30,FALSE()),"% como entero (60 en vez de 0,6)?",IF(IFERROR(ABS(F30)<=1,FALSE()),"redondeo","revisar"))))))
A31: D. Despliegue | B31: EV | C31: =EVM!G7 -> 0 | E31: =IF(D31="","",IF(ISNUMBER(D31),D31,IFERROR(VALUE(SUBSTITUTE(D31,".",MID(1/2,2,1))),IF(OR(UPPER(D31)="NULL",UPPER(D31)="N/A"),"null","TEXTO")))) | F31: =IF(AND(ISNUMBER(C31),ISNUMBER(E31)),E31-C31,"") | G31: =Datos!$B$12 -> 0.01 | H31: =IF(D31="","PENDIENTE",IF(ISNUMBER(C31),IF(ISNUMBER(E31),IF(ABS(F31)<=G31,"OK","DIFERENCIA"),"DIFERENCIA"),IF(E31="null","OK","DIFERENCIA"))) -> PENDIENTE | I31: =IF(H31<>"DIFERENCIA","",IF(AND(ISNUMBER(C31),E31="null"),"API da null y debería dar valor",IF(AND(NOT(ISNUMBER(C31)),ISNUMBER(E31)),"API da número y debería dar null",IF(E31="TEXTO","formato raro en la API",IF(IFERROR(ABS(E31-(C31*100))<=G31,FALSE()),"% como entero (60 en vez de 0,6)?",IF(IFERROR(ABS(F31)<=1,FALSE()),"redondeo","revisar"))))))
A32: D. Despliegue | B32: CV | C32: =EVM!H7 -> 0 | E32: =IF(D32="","",IF(ISNUMBER(D32),D32,IFERROR(VALUE(SUBSTITUTE(D32,".",MID(1/2,2,1))),IF(OR(UPPER(D32)="NULL",UPPER(D32)="N/A"),"null","TEXTO")))) | F32: =IF(AND(ISNUMBER(C32),ISNUMBER(E32)),E32-C32,"") | G32: =Datos!$B$12 -> 0.01 | H32: =IF(D32="","PENDIENTE",IF(ISNUMBER(C32),IF(ISNUMBER(E32),IF(ABS(F32)<=G32,"OK","DIFERENCIA"),"DIFERENCIA"),IF(E32="null","OK","DIFERENCIA"))) -> PENDIENTE | I32: =IF(H32<>"DIFERENCIA","",IF(AND(ISNUMBER(C32),E32="null"),"API da null y debería dar valor",IF(AND(NOT(ISNUMBER(C32)),ISNUMBER(E32)),"API da número y debería dar null",IF(E32="TEXTO","formato raro en la API",IF(IFERROR(ABS(E32-(C32*100))<=G32,FALSE()),"% como entero (60 en vez de 0,6)?",IF(IFERROR(ABS(F32)<=1,FALSE()),"redondeo","revisar"))))))
A33: D. Despliegue | B33: SV | C33: =EVM!I7 -> 0 | E33: =IF(D33="","",IF(ISNUMBER(D33),D33,IFERROR(VALUE(SUBSTITUTE(D33,".",MID(1/2,2,1))),IF(OR(UPPER(D33)="NULL",UPPER(D33)="N/A"),"null","TEXTO")))) | F33: =IF(AND(ISNUMBER(C33),ISNUMBER(E33)),E33-C33,"") | G33: =Datos!$B$12 -> 0.01 | H33: =IF(D33="","PENDIENTE",IF(ISNUMBER(C33),IF(ISNUMBER(E33),IF(ABS(F33)<=G33,"OK","DIFERENCIA"),"DIFERENCIA"),IF(E33="null","OK","DIFERENCIA"))) -> PENDIENTE | I33: =IF(H33<>"DIFERENCIA","",IF(AND(ISNUMBER(C33),E33="null"),"API da null y debería dar valor",IF(AND(NOT(ISNUMBER(C33)),ISNUMBER(E33)),"API da número y debería dar null",IF(E33="TEXTO","formato raro en la API",IF(IFERROR(ABS(E33-(C33*100))<=G33,FALSE()),"% como entero (60 en vez de 0,6)?",IF(IFERROR(ABS(F33)<=1,FALSE()),"redondeo","revisar"))))))
A34: D. Despliegue | B34: CPI | C34: =EVM!J7 -> N/A | E34: =IF(D34="","",IF(ISNUMBER(D34),D34,IFERROR(VALUE(SUBSTITUTE(D34,".",MID(1/2,2,1))),IF(OR(UPPER(D34)="NULL",UPPER(D34)="N/A"),"null","TEXTO")))) | F34: =IF(AND(ISNUMBER(C34),ISNUMBER(E34)),E34-C34,"") | G34: =Datos!$B$11 -> 0.0001 | H34: =IF(D34="","PENDIENTE",IF(ISNUMBER(C34),IF(ISNUMBER(E34),IF(ABS(F34)<=G34,"OK","DIFERENCIA"),"DIFERENCIA"),IF(E34="null","OK","DIFERENCIA"))) -> PENDIENTE | I34: =IF(H34<>"DIFERENCIA","",IF(AND(ISNUMBER(C34),E34="null"),"API da null y debería dar valor",IF(AND(NOT(ISNUMBER(C34)),ISNUMBER(E34)),"API da número y debería dar null",IF(E34="TEXTO","formato raro en la API",IF(IFERROR(ABS(E34-(C34*100))<=G34,FALSE()),"% como entero (60 en vez de 0,6)?",IF(IFERROR(ABS(F34)<=1,FALSE()),"redondeo","revisar"))))))
A35: D. Despliegue | B35: SPI | C35: =EVM!K7 -> N/A | E35: =IF(D35="","",IF(ISNUMBER(D35),D35,IFERROR(VALUE(SUBSTITUTE(D35,".",MID(1/2,2,1))),IF(OR(UPPER(D35)="NULL",UPPER(D35)="N/A"),"null","TEXTO")))) | F35: =IF(AND(ISNUMBER(C35),ISNUMBER(E35)),E35-C35,"") | G35: =Datos!$B$11 -> 0.0001 | H35: =IF(D35="","PENDIENTE",IF(ISNUMBER(C35),IF(ISNUMBER(E35),IF(ABS(F35)<=G35,"OK","DIFERENCIA"),"DIFERENCIA"),IF(E35="null","OK","DIFERENCIA"))) -> PENDIENTE | I35: =IF(H35<>"DIFERENCIA","",IF(AND(ISNUMBER(C35),E35="null"),"API da null y debería dar valor",IF(AND(NOT(ISNUMBER(C35)),ISNUMBER(E35)),"API da número y debería dar null",IF(E35="TEXTO","formato raro en la API",IF(IFERROR(ABS(E35-(C35*100))<=G35,FALSE()),"% como entero (60 en vez de 0,6)?",IF(IFERROR(ABS(F35)<=1,FALSE()),"redondeo","revisar"))))))
A36: D. Despliegue | B36: EAC | C36: =EVM!L7 -> N/A | E36: =IF(D36="","",IF(ISNUMBER(D36),D36,IFERROR(VALUE(SUBSTITUTE(D36,".",MID(1/2,2,1))),IF(OR(UPPER(D36)="NULL",UPPER(D36)="N/A"),"null","TEXTO")))) | F36: =IF(AND(ISNUMBER(C36),ISNUMBER(E36)),E36-C36,"") | G36: =Datos!$B$12 -> 0.01 | H36: =IF(D36="","PENDIENTE",IF(ISNUMBER(C36),IF(ISNUMBER(E36),IF(ABS(F36)<=G36,"OK","DIFERENCIA"),"DIFERENCIA"),IF(E36="null","OK","DIFERENCIA"))) -> PENDIENTE | I36: =IF(H36<>"DIFERENCIA","",IF(AND(ISNUMBER(C36),E36="null"),"API da null y debería dar valor",IF(AND(NOT(ISNUMBER(C36)),ISNUMBER(E36)),"API da número y debería dar null",IF(E36="TEXTO","formato raro en la API",IF(IFERROR(ABS(E36-(C36*100))<=G36,FALSE()),"% como entero (60 en vez de 0,6)?",IF(IFERROR(ABS(F36)<=1,FALSE()),"redondeo","revisar"))))))
A37: D. Despliegue | B37: VAC | C37: =EVM!M7 -> N/A | E37: =IF(D37="","",IF(ISNUMBER(D37),D37,IFERROR(VALUE(SUBSTITUTE(D37,".",MID(1/2,2,1))),IF(OR(UPPER(D37)="NULL",UPPER(D37)="N/A"),"null","TEXTO")))) | F37: =IF(AND(ISNUMBER(C37),ISNUMBER(E37)),E37-C37,"") | G37: =Datos!$B$12 -> 0.01 | H37: =IF(D37="","PENDIENTE",IF(ISNUMBER(C37),IF(ISNUMBER(E37),IF(ABS(F37)<=G37,"OK","DIFERENCIA"),"DIFERENCIA"),IF(E37="null","OK","DIFERENCIA"))) -> PENDIENTE | I37: =IF(H37<>"DIFERENCIA","",IF(AND(ISNUMBER(C37),E37="null"),"API da null y debería dar valor",IF(AND(NOT(ISNUMBER(C37)),ISNUMBER(E37)),"API da número y debería dar null",IF(E37="TEXTO","formato raro en la API",IF(IFERROR(ABS(E37-(C37*100))<=G37,FALSE()),"% como entero (60 en vez de 0,6)?",IF(IFERROR(ABS(F37)<=1,FALSE()),"redondeo","revisar"))))))
A38: Proyecto | B38: PV | C38: =EVM!F8 -> 52000000 | E38: =IF(D38="","",IF(ISNUMBER(D38),D38,IFERROR(VALUE(SUBSTITUTE(D38,".",MID(1/2,2,1))),IF(OR(UPPER(D38)="NULL",UPPER(D38)="N/A"),"null","TEXTO")))) | F38: =IF(AND(ISNUMBER(C38),ISNUMBER(E38)),E38-C38,"") | G38: =Datos!$B$12 -> 0.01 | H38: =IF(D38="","PENDIENTE",IF(ISNUMBER(C38),IF(ISNUMBER(E38),IF(ABS(F38)<=G38,"OK","DIFERENCIA"),"DIFERENCIA"),IF(E38="null","OK","DIFERENCIA"))) -> PENDIENTE | I38: =IF(H38<>"DIFERENCIA","",IF(AND(ISNUMBER(C38),E38="null"),"API da null y debería dar valor",IF(AND(NOT(ISNUMBER(C38)),ISNUMBER(E38)),"API da número y debería dar null",IF(E38="TEXTO","formato raro en la API",IF(IFERROR(ABS(E38-(C38*100))<=G38,FALSE()),"% como entero (60 en vez de 0,6)?",IF(IFERROR(ABS(F38)<=1,FALSE()),"redondeo","revisar"))))))
A39: Proyecto | B39: EV | C39: =EVM!G8 -> 43000000 | E39: =IF(D39="","",IF(ISNUMBER(D39),D39,IFERROR(VALUE(SUBSTITUTE(D39,".",MID(1/2,2,1))),IF(OR(UPPER(D39)="NULL",UPPER(D39)="N/A"),"null","TEXTO")))) | F39: =IF(AND(ISNUMBER(C39),ISNUMBER(E39)),E39-C39,"") | G39: =Datos!$B$12 -> 0.01 | H39: =IF(D39="","PENDIENTE",IF(ISNUMBER(C39),IF(ISNUMBER(E39),IF(ABS(F39)<=G39,"OK","DIFERENCIA"),"DIFERENCIA"),IF(E39="null","OK","DIFERENCIA"))) -> PENDIENTE | I39: =IF(H39<>"DIFERENCIA","",IF(AND(ISNUMBER(C39),E39="null"),"API da null y debería dar valor",IF(AND(NOT(ISNUMBER(C39)),ISNUMBER(E39)),"API da número y debería dar null",IF(E39="TEXTO","formato raro en la API",IF(IFERROR(ABS(E39-(C39*100))<=G39,FALSE()),"% como entero (60 en vez de 0,6)?",IF(IFERROR(ABS(F39)<=1,FALSE()),"redondeo","revisar"))))))
A40: Proyecto | B40: CV | C40: =EVM!H8 -> -2000000 | E40: =IF(D40="","",IF(ISNUMBER(D40),D40,IFERROR(VALUE(SUBSTITUTE(D40,".",MID(1/2,2,1))),IF(OR(UPPER(D40)="NULL",UPPER(D40)="N/A"),"null","TEXTO")))) | F40: =IF(AND(ISNUMBER(C40),ISNUMBER(E40)),E40-C40,"") | G40: =Datos!$B$12 -> 0.01 | H40: =IF(D40="","PENDIENTE",IF(ISNUMBER(C40),IF(ISNUMBER(E40),IF(ABS(F40)<=G40,"OK","DIFERENCIA"),"DIFERENCIA"),IF(E40="null","OK","DIFERENCIA"))) -> PENDIENTE | I40: =IF(H40<>"DIFERENCIA","",IF(AND(ISNUMBER(C40),E40="null"),"API da null y debería dar valor",IF(AND(NOT(ISNUMBER(C40)),ISNUMBER(E40)),"API da número y debería dar null",IF(E40="TEXTO","formato raro en la API",IF(IFERROR(ABS(E40-(C40*100))<=G40,FALSE()),"% como entero (60 en vez de 0,6)?",IF(IFERROR(ABS(F40)<=1,FALSE()),"redondeo","revisar"))))))
A41: Proyecto | B41: SV | C41: =EVM!I8 -> -9000000 | E41: =IF(D41="","",IF(ISNUMBER(D41),D41,IFERROR(VALUE(SUBSTITUTE(D41,".",MID(1/2,2,1))),IF(OR(UPPER(D41)="NULL",UPPER(D41)="N/A"),"null","TEXTO")))) | F41: =IF(AND(ISNUMBER(C41),ISNUMBER(E41)),E41-C41,"") | G41: =Datos!$B$12 -> 0.01 | H41: =IF(D41="","PENDIENTE",IF(ISNUMBER(C41),IF(ISNUMBER(E41),IF(ABS(F41)<=G41,"OK","DIFERENCIA"),"DIFERENCIA"),IF(E41="null","OK","DIFERENCIA"))) -> PENDIENTE | I41: =IF(H41<>"DIFERENCIA","",IF(AND(ISNUMBER(C41),E41="null"),"API da null y debería dar valor",IF(AND(NOT(ISNUMBER(C41)),ISNUMBER(E41)),"API da número y debería dar null",IF(E41="TEXTO","formato raro en la API",IF(IFERROR(ABS(E41-(C41*100))<=G41,FALSE()),"% como entero (60 en vez de 0,6)?",IF(IFERROR(ABS(F41)<=1,FALSE()),"redondeo","revisar"))))))
...

Sheet Notas
A1: Notas
A3: - Datos: ejercicio Portal de clientes (v2). Si el proyecto del repo trae otros valores, cambiar Datos!B4:E7.
A4: - Fórmulas del enunciado. El total del proyecto suma montos y recalcula los índices (no promedia).
A5: - No redondeo nada, los decimales que se ven son solo formato. Así se nota si la API redondea antes.
A6: - N/A aquí = null en la API. Si la API da null donde aquí hay N/A, cuenta como OK.
A7: - Tolerancias en Datos!B11:B12.
A8: - Solo sirve para 4 actividades; si hay más toca agregar filas en las tres hojas.
A9: - Los valores de la API los saco de /api-docs.
